2022-09-14 07:24:29,381 - 95497 - hummingbot.connector.exchange.digifinex.time_patcher - NETWORK - Error getting Digifinex server time.
Traceback (most recent call last):
  File "/opt/anaconda3/envs/hummingbot/lib/python3.8/site-packages/aiohttp/connector.py", line 999, in _create_direct_connection
    hosts = await asyncio.shield(host_resolved)
  File "/opt/anaconda3/envs/hummingbot/lib/python3.8/site-packages/aiohttp/connector.py", line 865, in _resolve_host
    addrs = await self._resolver.resolve(host, port, family=self._family)
  File "/opt/anaconda3/envs/hummingbot/lib/python3.8/site-packages/aiohttp/resolver.py", line 31, in resolve
    infos = await self._loop.getaddrinfo(
  File "/opt/anaconda3/envs/hummingbot/lib/python3.8/asyncio/base_events.py", line 825, in getaddrinfo
    return await self.run_in_executor(
  File "/opt/anaconda3/envs/hummingbot/lib/python3.8/concurrent/futures/thread.py", line 57, in run
    result = self.fn(*self.args, **self.kwargs)
  File "/opt/anaconda3/envs/hummingbot/lib/python3.8/socket.py", line 918, in getaddrinfo
    for res in _socket.getaddrinfo(host, port, family, type, proto, flags):
socket.gaierror: [Errno 8] nodename nor servname provided, or not known

The above exception was the direct cause of the following exception:

Traceback (most recent call last):
  File "/Users/clarasoutullo/projects/hummingbot/hummingbot/connector/exchange/digifinex/time_patcher.py", line 96, in update_server_time_offset
    server_time = await query_time_func()
  File "/Users/clarasoutullo/projects/hummingbot/hummingbot/connector/exchange/digifinex/digifinex_auth.py", line 40, in query_time_func
    async with session.get(Constants.REST_URL + '/time') as resp:
  File "/opt/anaconda3/envs/hummingbot/lib/python3.8/site-packages/aiohttp/client.py", line 1117, in __aenter__
    self._resp = await self._coro
  File "/opt/anaconda3/envs/hummingbot/lib/python3.8/site-packages/aiohttp/client.py", line 520, in _request
    conn = await self._connector.connect(
  File "/opt/anaconda3/envs/hummingbot/lib/python3.8/site-packages/aiohttp/connector.py", line 535, in connect
    proto = await self._create_connection(req, traces, timeout)
  File "/opt/anaconda3/envs/hummingbot/lib/python3.8/site-packages/aiohttp/connector.py", line 892, in _create_connection
    _, proto = await self._create_direct_connection(req, traces, timeout)
  File "/opt/anaconda3/envs/hummingbot/lib/python3.8/site-packages/aiohttp/connector.py", line 1011, in _create_direct_connection
    raise ClientConnectorError(req.connection_key, exc) from exc
aiohttp.client_exceptions.ClientConnectorError: Cannot connect to host openapi.digifinex.com:443 ssl:default [nodename nor servname provided, or not known]
2022-09-14 07:24:29,401 - 95497 - hummingbot.connector.exchange.digifinex.time_patcher - WARNING - Could not refresh Digifinex server time. Check network connection.
2022-09-14 07:39:45,567 - 95497 - hummingbot.connector.exchange.digifinex.time_patcher - NETWORK - Error getting Digifinex server time.
Traceback (most recent call last):
  File "/opt/anaconda3/envs/hummingbot/lib/python3.8/site-packages/aiohttp/connector.py", line 999, in _create_direct_connection
    hosts = await asyncio.shield(host_resolved)
  File "/opt/anaconda3/envs/hummingbot/lib/python3.8/site-packages/aiohttp/connector.py", line 865, in _resolve_host
    addrs = await self._resolver.resolve(host, port, family=self._family)
  File "/opt/anaconda3/envs/hummingbot/lib/python3.8/site-packages/aiohttp/resolver.py", line 31, in resolve
    infos = await self._loop.getaddrinfo(
  File "/opt/anaconda3/envs/hummingbot/lib/python3.8/asyncio/base_events.py", line 825, in getaddrinfo
    return await self.run_in_executor(
  File "/opt/anaconda3/envs/hummingbot/lib/python3.8/concurrent/futures/thread.py", line 57, in run
    result = self.fn(*self.args, **self.kwargs)
  File "/opt/anaconda3/envs/hummingbot/lib/python3.8/socket.py", line 918, in getaddrinfo
    for res in _socket.getaddrinfo(host, port, family, type, proto, flags):
socket.gaierror: [Errno 8] nodename nor servname provided, or not known

The above exception was the direct cause of the following exception:

Traceback (most recent call last):
  File "/Users/clarasoutullo/projects/hummingbot/hummingbot/connector/exchange/digifinex/time_patcher.py", line 96, in update_server_time_offset
    server_time = await query_time_func()
  File "/Users/clarasoutullo/projects/hummingbot/hummingbot/connector/exchange/digifinex/digifinex_auth.py", line 40, in query_time_func
    async with session.get(Constants.REST_URL + '/time') as resp:
  File "/opt/anaconda3/envs/hummingbot/lib/python3.8/site-packages/aiohttp/client.py", line 1117, in __aenter__
    self._resp = await self._coro
  File "/opt/anaconda3/envs/hummingbot/lib/python3.8/site-packages/aiohttp/client.py", line 520, in _request
    conn = await self._connector.connect(
  File "/opt/anaconda3/envs/hummingbot/lib/python3.8/site-packages/aiohttp/connector.py", line 535, in connect
    proto = await self._create_connection(req, traces, timeout)
  File "/opt/anaconda3/envs/hummingbot/lib/python3.8/site-packages/aiohttp/connector.py", line 892, in _create_connection
    _, proto = await self._create_direct_connection(req, traces, timeout)
  File "/opt/anaconda3/envs/hummingbot/lib/python3.8/site-packages/aiohttp/connector.py", line 1011, in _create_direct_connection
    raise ClientConnectorError(req.connection_key, exc) from exc
aiohttp.client_exceptions.ClientConnectorError: Cannot connect to host openapi.digifinex.com:443 ssl:default [nodename nor servname provided, or not known]
2022-09-14 07:39:45,569 - 95497 - hummingbot.connector.exchange.digifinex.time_patcher - WARNING - Could not refresh Digifinex server time. Check network connection.
2022-09-14 07:54:59,838 - 95497 - hummingbot.connector.exchange.digifinex.time_patcher - NETWORK - Error getting Digifinex server time.
Traceback (most recent call last):
  File "/opt/anaconda3/envs/hummingbot/lib/python3.8/site-packages/aiohttp/connector.py", line 999, in _create_direct_connection
    hosts = await asyncio.shield(host_resolved)
  File "/opt/anaconda3/envs/hummingbot/lib/python3.8/site-packages/aiohttp/connector.py", line 865, in _resolve_host
    addrs = await self._resolver.resolve(host, port, family=self._family)
  File "/opt/anaconda3/envs/hummingbot/lib/python3.8/site-packages/aiohttp/resolver.py", line 31, in resolve
    infos = await self._loop.getaddrinfo(
  File "/opt/anaconda3/envs/hummingbot/lib/python3.8/asyncio/base_events.py", line 825, in getaddrinfo
    return await self.run_in_executor(
  File "/opt/anaconda3/envs/hummingbot/lib/python3.8/concurrent/futures/thread.py", line 57, in run
    result = self.fn(*self.args, **self.kwargs)
  File "/opt/anaconda3/envs/hummingbot/lib/python3.8/socket.py", line 918, in getaddrinfo
    for res in _socket.getaddrinfo(host, port, family, type, proto, flags):
socket.gaierror: [Errno 8] nodename nor servname provided, or not known

The above exception was the direct cause of the following exception:

Traceback (most recent call last):
  File "/Users/clarasoutullo/projects/hummingbot/hummingbot/connector/exchange/digifinex/time_patcher.py", line 96, in update_server_time_offset
    server_time = await query_time_func()
  File "/Users/clarasoutullo/projects/hummingbot/hummingbot/connector/exchange/digifinex/digifinex_auth.py", line 40, in query_time_func
    async with session.get(Constants.REST_URL + '/time') as resp:
  File "/opt/anaconda3/envs/hummingbot/lib/python3.8/site-packages/aiohttp/client.py", line 1117, in __aenter__
    self._resp = await self._coro
  File "/opt/anaconda3/envs/hummingbot/lib/python3.8/site-packages/aiohttp/client.py", line 520, in _request
    conn = await self._connector.connect(
  File "/opt/anaconda3/envs/hummingbot/lib/python3.8/site-packages/aiohttp/connector.py", line 535, in connect
    proto = await self._create_connection(req, traces, timeout)
  File "/opt/anaconda3/envs/hummingbot/lib/python3.8/site-packages/aiohttp/connector.py", line 892, in _create_connection
    _, proto = await self._create_direct_connection(req, traces, timeout)
  File "/opt/anaconda3/envs/hummingbot/lib/python3.8/site-packages/aiohttp/connector.py", line 1011, in _create_direct_connection
    raise ClientConnectorError(req.connection_key, exc) from exc
aiohttp.client_exceptions.ClientConnectorError: Cannot connect to host openapi.digifinex.com:443 ssl:default [nodename nor servname provided, or not known]
2022-09-14 07:54:59,843 - 95497 - hummingbot.connector.exchange.digifinex.time_patcher - WARNING - Could not refresh Digifinex server time. Check network connection.
2022-09-14 08:16:42,669 - 95497 - hummingbot.connector.exchange.digifinex.time_patcher - NETWORK - Error getting Digifinex server time.
Traceback (most recent call last):
  File "/opt/anaconda3/envs/hummingbot/lib/python3.8/site-packages/aiohttp/connector.py", line 999, in _create_direct_connection
    hosts = await asyncio.shield(host_resolved)
  File "/opt/anaconda3/envs/hummingbot/lib/python3.8/site-packages/aiohttp/connector.py", line 865, in _resolve_host
    addrs = await self._resolver.resolve(host, port, family=self._family)
  File "/opt/anaconda3/envs/hummingbot/lib/python3.8/site-packages/aiohttp/resolver.py", line 31, in resolve
    infos = await self._loop.getaddrinfo(
  File "/opt/anaconda3/envs/hummingbot/lib/python3.8/asyncio/base_events.py", line 825, in getaddrinfo
    return await self.run_in_executor(
  File "/opt/anaconda3/envs/hummingbot/lib/python3.8/concurrent/futures/thread.py", line 57, in run
    result = self.fn(*self.args, **self.kwargs)
  File "/opt/anaconda3/envs/hummingbot/lib/python3.8/socket.py", line 918, in getaddrinfo
    for res in _socket.getaddrinfo(host, port, family, type, proto, flags):
socket.gaierror: [Errno 8] nodename nor servname provided, or not known

The above exception was the direct cause of the following exception:

Traceback (most recent call last):
  File "/Users/clarasoutullo/projects/hummingbot/hummingbot/connector/exchange/digifinex/time_patcher.py", line 96, in update_server_time_offset
    server_time = await query_time_func()
  File "/Users/clarasoutullo/projects/hummingbot/hummingbot/connector/exchange/digifinex/digifinex_auth.py", line 40, in query_time_func
    async with session.get(Constants.REST_URL + '/time') as resp:
  File "/opt/anaconda3/envs/hummingbot/lib/python3.8/site-packages/aiohttp/client.py", line 1117, in __aenter__
    self._resp = await self._coro
  File "/opt/anaconda3/envs/hummingbot/lib/python3.8/site-packages/aiohttp/client.py", line 520, in _request
    conn = await self._connector.connect(
  File "/opt/anaconda3/envs/hummingbot/lib/python3.8/site-packages/aiohttp/connector.py", line 535, in connect
    proto = await self._create_connection(req, traces, timeout)
  File "/opt/anaconda3/envs/hummingbot/lib/python3.8/site-packages/aiohttp/connector.py", line 892, in _create_connection
    _, proto = await self._create_direct_connection(req, traces, timeout)
  File "/opt/anaconda3/envs/hummingbot/lib/python3.8/site-packages/aiohttp/connector.py", line 1011, in _create_direct_connection
    raise ClientConnectorError(req.connection_key, exc) from exc
aiohttp.client_exceptions.ClientConnectorError: Cannot connect to host openapi.digifinex.com:443 ssl:default [nodename nor servname provided, or not known]
2022-09-14 08:16:42,670 - 95497 - hummingbot.connector.exchange.digifinex.time_patcher - WARNING - Could not refresh Digifinex server time. Check network connection.
2022-09-14 08:32:00,569 - 95497 - hummingbot.connector.exchange.digifinex.time_patcher - NETWORK - Error getting Digifinex server time.
Traceback (most recent call last):
  File "/opt/anaconda3/envs/hummingbot/lib/python3.8/site-packages/aiohttp/connector.py", line 999, in _create_direct_connection
    hosts = await asyncio.shield(host_resolved)
  File "/opt/anaconda3/envs/hummingbot/lib/python3.8/site-packages/aiohttp/connector.py", line 865, in _resolve_host
    addrs = await self._resolver.resolve(host, port, family=self._family)
  File "/opt/anaconda3/envs/hummingbot/lib/python3.8/site-packages/aiohttp/resolver.py", line 31, in resolve
    infos = await self._loop.getaddrinfo(
  File "/opt/anaconda3/envs/hummingbot/lib/python3.8/asyncio/base_events.py", line 825, in getaddrinfo
    return await self.run_in_executor(
  File "/opt/anaconda3/envs/hummingbot/lib/python3.8/concurrent/futures/thread.py", line 57, in run
    result = self.fn(*self.args, **self.kwargs)
  File "/opt/anaconda3/envs/hummingbot/lib/python3.8/socket.py", line 918, in getaddrinfo
    for res in _socket.getaddrinfo(host, port, family, type, proto, flags):
socket.gaierror: [Errno 8] nodename nor servname provided, or not known

The above exception was the direct cause of the following exception:

Traceback (most recent call last):
  File "/Users/clarasoutullo/projects/hummingbot/hummingbot/connector/exchange/digifinex/time_patcher.py", line 96, in update_server_time_offset
    server_time = await query_time_func()
  File "/Users/clarasoutullo/projects/hummingbot/hummingbot/connector/exchange/digifinex/digifinex_auth.py", line 40, in query_time_func
    async with session.get(Constants.REST_URL + '/time') as resp:
  File "/opt/anaconda3/envs/hummingbot/lib/python3.8/site-packages/aiohttp/client.py", line 1117, in __aenter__
    self._resp = await self._coro
  File "/opt/anaconda3/envs/hummingbot/lib/python3.8/site-packages/aiohttp/client.py", line 520, in _request
    conn = await self._connector.connect(
  File "/opt/anaconda3/envs/hummingbot/lib/python3.8/site-packages/aiohttp/connector.py", line 535, in connect
    proto = await self._create_connection(req, traces, timeout)
  File "/opt/anaconda3/envs/hummingbot/lib/python3.8/site-packages/aiohttp/connector.py", line 892, in _create_connection
    _, proto = await self._create_direct_connection(req, traces, timeout)
  File "/opt/anaconda3/envs/hummingbot/lib/python3.8/site-packages/aiohttp/connector.py", line 1011, in _create_direct_connection
    raise ClientConnectorError(req.connection_key, exc) from exc
aiohttp.client_exceptions.ClientConnectorError: Cannot connect to host openapi.digifinex.com:443 ssl:default [nodename nor servname provided, or not known]
2022-09-14 08:32:00,572 - 95497 - hummingbot.connector.exchange.digifinex.time_patcher - WARNING - Could not refresh Digifinex server time. Check network connection.
2022-09-14 08:38:40,624 - 95497 - hummingbot.connector.exchange.digifinex.time_patcher - NETWORK - Error getting Digifinex server time.
Traceback (most recent call last):
  File "/opt/anaconda3/envs/hummingbot/lib/python3.8/site-packages/aiohttp/connector.py", line 999, in _create_direct_connection
    hosts = await asyncio.shield(host_resolved)
  File "/opt/anaconda3/envs/hummingbot/lib/python3.8/site-packages/aiohttp/connector.py", line 865, in _resolve_host
    addrs = await self._resolver.resolve(host, port, family=self._family)
  File "/opt/anaconda3/envs/hummingbot/lib/python3.8/site-packages/aiohttp/resolver.py", line 31, in resolve
    infos = await self._loop.getaddrinfo(
  File "/opt/anaconda3/envs/hummingbot/lib/python3.8/asyncio/base_events.py", line 825, in getaddrinfo
    return await self.run_in_executor(
  File "/opt/anaconda3/envs/hummingbot/lib/python3.8/concurrent/futures/thread.py", line 57, in run
    result = self.fn(*self.args, **self.kwargs)
  File "/opt/anaconda3/envs/hummingbot/lib/python3.8/socket.py", line 918, in getaddrinfo
    for res in _socket.getaddrinfo(host, port, family, type, proto, flags):
socket.gaierror: [Errno 8] nodename nor servname provided, or not known

The above exception was the direct cause of the following exception:

Traceback (most recent call last):
  File "/Users/clarasoutullo/projects/hummingbot/hummingbot/connector/exchange/digifinex/time_patcher.py", line 96, in update_server_time_offset
    server_time = await query_time_func()
  File "/Users/clarasoutullo/projects/hummingbot/hummingbot/connector/exchange/digifinex/digifinex_auth.py", line 40, in query_time_func
    async with session.get(Constants.REST_URL + '/time') as resp:
  File "/opt/anaconda3/envs/hummingbot/lib/python3.8/site-packages/aiohttp/client.py", line 1117, in __aenter__
    self._resp = await self._coro
  File "/opt/anaconda3/envs/hummingbot/lib/python3.8/site-packages/aiohttp/client.py", line 520, in _request
    conn = await self._connector.connect(
  File "/opt/anaconda3/envs/hummingbot/lib/python3.8/site-packages/aiohttp/connector.py", line 535, in connect
    proto = await self._create_connection(req, traces, timeout)
  File "/opt/anaconda3/envs/hummingbot/lib/python3.8/site-packages/aiohttp/connector.py", line 892, in _create_connection
    _, proto = await self._create_direct_connection(req, traces, timeout)
  File "/opt/anaconda3/envs/hummingbot/lib/python3.8/site-packages/aiohttp/connector.py", line 1011, in _create_direct_connection
    raise ClientConnectorError(req.connection_key, exc) from exc
aiohttp.client_exceptions.ClientConnectorError: Cannot connect to host openapi.digifinex.com:443 ssl:default [nodename nor servname provided, or not known]
2022-09-14 08:38:40,629 - 95497 - hummingbot.connector.exchange.digifinex.time_patcher - WARNING - Could not refresh Digifinex server time. Check network connection.
2022-09-14 08:39:47,434 - 95497 - hummingbot.connector.exchange.digifinex.time_patcher - NETWORK - Error getting Digifinex server time.
Traceback (most recent call last):
  File "/opt/anaconda3/envs/hummingbot/lib/python3.8/site-packages/aiohttp/connector.py", line 999, in _create_direct_connection
    hosts = await asyncio.shield(host_resolved)
  File "/opt/anaconda3/envs/hummingbot/lib/python3.8/site-packages/aiohttp/connector.py", line 865, in _resolve_host
    addrs = await self._resolver.resolve(host, port, family=self._family)
  File "/opt/anaconda3/envs/hummingbot/lib/python3.8/site-packages/aiohttp/resolver.py", line 31, in resolve
    infos = await self._loop.getaddrinfo(
  File "/opt/anaconda3/envs/hummingbot/lib/python3.8/asyncio/base_events.py", line 825, in getaddrinfo
    return await self.run_in_executor(
  File "/opt/anaconda3/envs/hummingbot/lib/python3.8/concurrent/futures/thread.py", line 57, in run
    result = self.fn(*self.args, **self.kwargs)
  File "/opt/anaconda3/envs/hummingbot/lib/python3.8/socket.py", line 918, in getaddrinfo
    for res in _socket.getaddrinfo(host, port, family, type, proto, flags):
socket.gaierror: [Errno 8] nodename nor servname provided, or not known

The above exception was the direct cause of the following exception:

Traceback (most recent call last):
  File "/Users/clarasoutullo/projects/hummingbot/hummingbot/connector/exchange/digifinex/time_patcher.py", line 96, in update_server_time_offset
    server_time = await query_time_func()
  File "/Users/clarasoutullo/projects/hummingbot/hummingbot/connector/exchange/digifinex/digifinex_auth.py", line 40, in query_time_func
    async with session.get(Constants.REST_URL + '/time') as resp:
  File "/opt/anaconda3/envs/hummingbot/lib/python3.8/site-packages/aiohttp/client.py", line 1117, in __aenter__
    self._resp = await self._coro
  File "/opt/anaconda3/envs/hummingbot/lib/python3.8/site-packages/aiohttp/client.py", line 520, in _request
    conn = await self._connector.connect(
  File "/opt/anaconda3/envs/hummingbot/lib/python3.8/site-packages/aiohttp/connector.py", line 535, in connect
    proto = await self._create_connection(req, traces, timeout)
  File "/opt/anaconda3/envs/hummingbot/lib/python3.8/site-packages/aiohttp/connector.py", line 892, in _create_connection
    _, proto = await self._create_direct_connection(req, traces, timeout)
  File "/opt/anaconda3/envs/hummingbot/lib/python3.8/site-packages/aiohttp/connector.py", line 1011, in _create_direct_connection
    raise ClientConnectorError(req.connection_key, exc) from exc
aiohttp.client_exceptions.ClientConnectorError: Cannot connect to host openapi.digifinex.com:443 ssl:default [nodename nor servname provided, or not known]
2022-09-14 08:39:47,437 - 95497 - hummingbot.connector.exchange.digifinex.time_patcher - WARNING - Could not refresh Digifinex server time. Check network connection.
2022-09-14 08:41:27,823 - 95497 - hummingbot.connector.exchange.digifinex.time_patcher - NETWORK - Error getting Digifinex server time.
Traceback (most recent call last):
  File "/opt/anaconda3/envs/hummingbot/lib/python3.8/site-packages/aiohttp/connector.py", line 999, in _create_direct_connection
    hosts = await asyncio.shield(host_resolved)
  File "/opt/anaconda3/envs/hummingbot/lib/python3.8/site-packages/aiohttp/connector.py", line 865, in _resolve_host
    addrs = await self._resolver.resolve(host, port, family=self._family)
  File "/opt/anaconda3/envs/hummingbot/lib/python3.8/site-packages/aiohttp/resolver.py", line 31, in resolve
    infos = await self._loop.getaddrinfo(
  File "/opt/anaconda3/envs/hummingbot/lib/python3.8/asyncio/base_events.py", line 825, in getaddrinfo
    return await self.run_in_executor(
  File "/opt/anaconda3/envs/hummingbot/lib/python3.8/concurrent/futures/thread.py", line 57, in run
    result = self.fn(*self.args, **self.kwargs)
  File "/opt/anaconda3/envs/hummingbot/lib/python3.8/socket.py", line 918, in getaddrinfo
    for res in _socket.getaddrinfo(host, port, family, type, proto, flags):
socket.gaierror: [Errno 8] nodename nor servname provided, or not known

The above exception was the direct cause of the following exception:

Traceback (most recent call last):
  File "/Users/clarasoutullo/projects/hummingbot/hummingbot/connector/exchange/digifinex/time_patcher.py", line 96, in update_server_time_offset
    server_time = await query_time_func()
  File "/Users/clarasoutullo/projects/hummingbot/hummingbot/connector/exchange/digifinex/digifinex_auth.py", line 40, in query_time_func
    async with session.get(Constants.REST_URL + '/time') as resp:
  File "/opt/anaconda3/envs/hummingbot/lib/python3.8/site-packages/aiohttp/client.py", line 1117, in __aenter__
    self._resp = await self._coro
  File "/opt/anaconda3/envs/hummingbot/lib/python3.8/site-packages/aiohttp/client.py", line 520, in _request
    conn = await self._connector.connect(
  File "/opt/anaconda3/envs/hummingbot/lib/python3.8/site-packages/aiohttp/connector.py", line 535, in connect
    proto = await self._create_connection(req, traces, timeout)
  File "/opt/anaconda3/envs/hummingbot/lib/python3.8/site-packages/aiohttp/connector.py", line 892, in _create_connection
    _, proto = await self._create_direct_connection(req, traces, timeout)
  File "/opt/anaconda3/envs/hummingbot/lib/python3.8/site-packages/aiohttp/connector.py", line 1011, in _create_direct_connection
    raise ClientConnectorError(req.connection_key, exc) from exc
aiohttp.client_exceptions.ClientConnectorError: Cannot connect to host openapi.digifinex.com:443 ssl:default [nodename nor servname provided, or not known]
2022-09-14 08:41:27,828 - 95497 - hummingbot.connector.exchange.digifinex.time_patcher - WARNING - Could not refresh Digifinex server time. Check network connection.
2022-09-14 08:43:41,739 - 95497 - hummingbot.connector.exchange.digifinex.time_patcher - NETWORK - Error getting Digifinex server time.
Traceback (most recent call last):
  File "/opt/anaconda3/envs/hummingbot/lib/python3.8/site-packages/aiohttp/connector.py", line 999, in _create_direct_connection
    hosts = await asyncio.shield(host_resolved)
  File "/opt/anaconda3/envs/hummingbot/lib/python3.8/site-packages/aiohttp/connector.py", line 865, in _resolve_host
    addrs = await self._resolver.resolve(host, port, family=self._family)
  File "/opt/anaconda3/envs/hummingbot/lib/python3.8/site-packages/aiohttp/resolver.py", line 31, in resolve
    infos = await self._loop.getaddrinfo(
  File "/opt/anaconda3/envs/hummingbot/lib/python3.8/asyncio/base_events.py", line 825, in getaddrinfo
    return await self.run_in_executor(
  File "/opt/anaconda3/envs/hummingbot/lib/python3.8/concurrent/futures/thread.py", line 57, in run
    result = self.fn(*self.args, **self.kwargs)
  File "/opt/anaconda3/envs/hummingbot/lib/python3.8/socket.py", line 918, in getaddrinfo
    for res in _socket.getaddrinfo(host, port, family, type, proto, flags):
socket.gaierror: [Errno 8] nodename nor servname provided, or not known

The above exception was the direct cause of the following exception:

Traceback (most recent call last):
  File "/Users/clarasoutullo/projects/hummingbot/hummingbot/connector/exchange/digifinex/time_patcher.py", line 96, in update_server_time_offset
    server_time = await query_time_func()
  File "/Users/clarasoutullo/projects/hummingbot/hummingbot/connector/exchange/digifinex/digifinex_auth.py", line 40, in query_time_func
    async with session.get(Constants.REST_URL + '/time') as resp:
  File "/opt/anaconda3/envs/hummingbot/lib/python3.8/site-packages/aiohttp/client.py", line 1117, in __aenter__
    self._resp = await self._coro
  File "/opt/anaconda3/envs/hummingbot/lib/python3.8/site-packages/aiohttp/client.py", line 520, in _request
    conn = await self._connector.connect(
  File "/opt/anaconda3/envs/hummingbot/lib/python3.8/site-packages/aiohttp/connector.py", line 535, in connect
    proto = await self._create_connection(req, traces, timeout)
  File "/opt/anaconda3/envs/hummingbot/lib/python3.8/site-packages/aiohttp/connector.py", line 892, in _create_connection
    _, proto = await self._create_direct_connection(req, traces, timeout)
  File "/opt/anaconda3/envs/hummingbot/lib/python3.8/site-packages/aiohttp/connector.py", line 1011, in _create_direct_connection
    raise ClientConnectorError(req.connection_key, exc) from exc
aiohttp.client_exceptions.ClientConnectorError: Cannot connect to host openapi.digifinex.com:443 ssl:default [nodename nor servname provided, or not known]
2022-09-14 08:43:41,743 - 95497 - hummingbot.connector.exchange.digifinex.time_patcher - WARNING - Could not refresh Digifinex server time. Check network connection.
2022-09-14 08:46:02,465 - 95497 - hummingbot.connector.exchange.digifinex.time_patcher - NETWORK - Error getting Digifinex server time.
Traceback (most recent call last):
  File "/opt/anaconda3/envs/hummingbot/lib/python3.8/site-packages/aiohttp/connector.py", line 999, in _create_direct_connection
    hosts = await asyncio.shield(host_resolved)
  File "/opt/anaconda3/envs/hummingbot/lib/python3.8/site-packages/aiohttp/connector.py", line 865, in _resolve_host
    addrs = await self._resolver.resolve(host, port, family=self._family)
  File "/opt/anaconda3/envs/hummingbot/lib/python3.8/site-packages/aiohttp/resolver.py", line 31, in resolve
    infos = await self._loop.getaddrinfo(
  File "/opt/anaconda3/envs/hummingbot/lib/python3.8/asyncio/base_events.py", line 825, in getaddrinfo
    return await self.run_in_executor(
  File "/opt/anaconda3/envs/hummingbot/lib/python3.8/concurrent/futures/thread.py", line 57, in run
    result = self.fn(*self.args, **self.kwargs)
  File "/opt/anaconda3/envs/hummingbot/lib/python3.8/socket.py", line 918, in getaddrinfo
    for res in _socket.getaddrinfo(host, port, family, type, proto, flags):
socket.gaierror: [Errno 8] nodename nor servname provided, or not known

The above exception was the direct cause of the following exception:

Traceback (most recent call last):
  File "/Users/clarasoutullo/projects/hummingbot/hummingbot/connector/exchange/digifinex/time_patcher.py", line 96, in update_server_time_offset
    server_time = await query_time_func()
  File "/Users/clarasoutullo/projects/hummingbot/hummingbot/connector/exchange/digifinex/digifinex_auth.py", line 40, in query_time_func
    async with session.get(Constants.REST_URL + '/time') as resp:
  File "/opt/anaconda3/envs/hummingbot/lib/python3.8/site-packages/aiohttp/client.py", line 1117, in __aenter__
    self._resp = await self._coro
  File "/opt/anaconda3/envs/hummingbot/lib/python3.8/site-packages/aiohttp/client.py", line 520, in _request
    conn = await self._connector.connect(
  File "/opt/anaconda3/envs/hummingbot/lib/python3.8/site-packages/aiohttp/connector.py", line 535, in connect
    proto = await self._create_connection(req, traces, timeout)
  File "/opt/anaconda3/envs/hummingbot/lib/python3.8/site-packages/aiohttp/connector.py", line 892, in _create_connection
    _, proto = await self._create_direct_connection(req, traces, timeout)
  File "/opt/anaconda3/envs/hummingbot/lib/python3.8/site-packages/aiohttp/connector.py", line 1011, in _create_direct_connection
    raise ClientConnectorError(req.connection_key, exc) from exc
aiohttp.client_exceptions.ClientConnectorError: Cannot connect to host openapi.digifinex.com:443 ssl:default [nodename nor servname provided, or not known]
2022-09-14 08:46:02,469 - 95497 - hummingbot.connector.exchange.digifinex.time_patcher - WARNING - Could not refresh Digifinex server time. Check network connection.
2022-09-14 08:47:24,687 - 95497 - hummingbot.connector.exchange.digifinex.time_patcher - NETWORK - Error getting Digifinex server time.
Traceback (most recent call last):
  File "/opt/anaconda3/envs/hummingbot/lib/python3.8/site-packages/aiohttp/connector.py", line 999, in _create_direct_connection
    hosts = await asyncio.shield(host_resolved)
  File "/opt/anaconda3/envs/hummingbot/lib/python3.8/site-packages/aiohttp/connector.py", line 865, in _resolve_host
    addrs = await self._resolver.resolve(host, port, family=self._family)
  File "/opt/anaconda3/envs/hummingbot/lib/python3.8/site-packages/aiohttp/resolver.py", line 31, in resolve
    infos = await self._loop.getaddrinfo(
  File "/opt/anaconda3/envs/hummingbot/lib/python3.8/asyncio/base_events.py", line 825, in getaddrinfo
    return await self.run_in_executor(
  File "/opt/anaconda3/envs/hummingbot/lib/python3.8/concurrent/futures/thread.py", line 57, in run
    result = self.fn(*self.args, **self.kwargs)
  File "/opt/anaconda3/envs/hummingbot/lib/python3.8/socket.py", line 918, in getaddrinfo
    for res in _socket.getaddrinfo(host, port, family, type, proto, flags):
socket.gaierror: [Errno 8] nodename nor servname provided, or not known

The above exception was the direct cause of the following exception:

Traceback (most recent call last):
  File "/Users/clarasoutullo/projects/hummingbot/hummingbot/connector/exchange/digifinex/time_patcher.py", line 96, in update_server_time_offset
    server_time = await query_time_func()
  File "/Users/clarasoutullo/projects/hummingbot/hummingbot/connector/exchange/digifinex/digifinex_auth.py", line 40, in query_time_func
    async with session.get(Constants.REST_URL + '/time') as resp:
  File "/opt/anaconda3/envs/hummingbot/lib/python3.8/site-packages/aiohttp/client.py", line 1117, in __aenter__
    self._resp = await self._coro
  File "/opt/anaconda3/envs/hummingbot/lib/python3.8/site-packages/aiohttp/client.py", line 520, in _request
    conn = await self._connector.connect(
  File "/opt/anaconda3/envs/hummingbot/lib/python3.8/site-packages/aiohttp/connector.py", line 535, in connect
    proto = await self._create_connection(req, traces, timeout)
  File "/opt/anaconda3/envs/hummingbot/lib/python3.8/site-packages/aiohttp/connector.py", line 892, in _create_connection
    _, proto = await self._create_direct_connection(req, traces, timeout)
  File "/opt/anaconda3/envs/hummingbot/lib/python3.8/site-packages/aiohttp/connector.py", line 1011, in _create_direct_connection
    raise ClientConnectorError(req.connection_key, exc) from exc
aiohttp.client_exceptions.ClientConnectorError: Cannot connect to host openapi.digifinex.com:443 ssl:default [nodename nor servname provided, or not known]
2022-09-14 08:47:24,688 - 95497 - hummingbot.connector.exchange.digifinex.time_patcher - WARNING - Could not refresh Digifinex server time. Check network connection.
2022-09-14 08:48:24,700 - 95497 - hummingbot.connector.exchange.digifinex.time_patcher - NETWORK - Error getting Digifinex server time.
Traceback (most recent call last):
  File "/opt/anaconda3/envs/hummingbot/lib/python3.8/site-packages/aiohttp/connector.py", line 999, in _create_direct_connection
    hosts = await asyncio.shield(host_resolved)
  File "/opt/anaconda3/envs/hummingbot/lib/python3.8/site-packages/aiohttp/connector.py", line 865, in _resolve_host
    addrs = await self._resolver.resolve(host, port, family=self._family)
  File "/opt/anaconda3/envs/hummingbot/lib/python3.8/site-packages/aiohttp/resolver.py", line 31, in resolve
    infos = await self._loop.getaddrinfo(
  File "/opt/anaconda3/envs/hummingbot/lib/python3.8/asyncio/base_events.py", line 825, in getaddrinfo
    return await self.run_in_executor(
  File "/opt/anaconda3/envs/hummingbot/lib/python3.8/concurrent/futures/thread.py", line 57, in run
    result = self.fn(*self.args, **self.kwargs)
  File "/opt/anaconda3/envs/hummingbot/lib/python3.8/socket.py", line 918, in getaddrinfo
    for res in _socket.getaddrinfo(host, port, family, type, proto, flags):
socket.gaierror: [Errno 8] nodename nor servname provided, or not known

The above exception was the direct cause of the following exception:

Traceback (most recent call last):
  File "/Users/clarasoutullo/projects/hummingbot/hummingbot/connector/exchange/digifinex/time_patcher.py", line 96, in update_server_time_offset
    server_time = await query_time_func()
  File "/Users/clarasoutullo/projects/hummingbot/hummingbot/connector/exchange/digifinex/digifinex_auth.py", line 40, in query_time_func
    async with session.get(Constants.REST_URL + '/time') as resp:
  File "/opt/anaconda3/envs/hummingbot/lib/python3.8/site-packages/aiohttp/client.py", line 1117, in __aenter__
    self._resp = await self._coro
  File "/opt/anaconda3/envs/hummingbot/lib/python3.8/site-packages/aiohttp/client.py", line 520, in _request
    conn = await self._connector.connect(
  File "/opt/anaconda3/envs/hummingbot/lib/python3.8/site-packages/aiohttp/connector.py", line 535, in connect
    proto = await self._create_connection(req, traces, timeout)
  File "/opt/anaconda3/envs/hummingbot/lib/python3.8/site-packages/aiohttp/connector.py", line 892, in _create_connection
    _, proto = await self._create_direct_connection(req, traces, timeout)
  File "/opt/anaconda3/envs/hummingbot/lib/python3.8/site-packages/aiohttp/connector.py", line 1011, in _create_direct_connection
    raise ClientConnectorError(req.connection_key, exc) from exc
aiohttp.client_exceptions.ClientConnectorError: Cannot connect to host openapi.digifinex.com:443 ssl:default [nodename nor servname provided, or not known]
2022-09-14 08:48:24,706 - 95497 - hummingbot.connector.exchange.digifinex.time_patcher - WARNING - Could not refresh Digifinex server time. Check network connection.
2022-09-14 08:49:24,759 - 95497 - hummingbot.connector.exchange.digifinex.time_patcher - NETWORK - Error getting Digifinex server time.
Traceback (most recent call last):
  File "/opt/anaconda3/envs/hummingbot/lib/python3.8/site-packages/aiohttp/connector.py", line 999, in _create_direct_connection
    hosts = await asyncio.shield(host_resolved)
  File "/opt/anaconda3/envs/hummingbot/lib/python3.8/site-packages/aiohttp/connector.py", line 865, in _resolve_host
    addrs = await self._resolver.resolve(host, port, family=self._family)
  File "/opt/anaconda3/envs/hummingbot/lib/python3.8/site-packages/aiohttp/resolver.py", line 31, in resolve
    infos = await self._loop.getaddrinfo(
  File "/opt/anaconda3/envs/hummingbot/lib/python3.8/asyncio/base_events.py", line 825, in getaddrinfo
    return await self.run_in_executor(
  File "/opt/anaconda3/envs/hummingbot/lib/python3.8/concurrent/futures/thread.py", line 57, in run
    result = self.fn(*self.args, **self.kwargs)
  File "/opt/anaconda3/envs/hummingbot/lib/python3.8/socket.py", line 918, in getaddrinfo
    for res in _socket.getaddrinfo(host, port, family, type, proto, flags):
socket.gaierror: [Errno 8] nodename nor servname provided, or not known

The above exception was the direct cause of the following exception:

Traceback (most recent call last):
  File "/Users/clarasoutullo/projects/hummingbot/hummingbot/connector/exchange/digifinex/time_patcher.py", line 96, in update_server_time_offset
    server_time = await query_time_func()
  File "/Users/clarasoutullo/projects/hummingbot/hummingbot/connector/exchange/digifinex/digifinex_auth.py", line 40, in query_time_func
    async with session.get(Constants.REST_URL + '/time') as resp:
  File "/opt/anaconda3/envs/hummingbot/lib/python3.8/site-packages/aiohttp/client.py", line 1117, in __aenter__
    self._resp = await self._coro
  File "/opt/anaconda3/envs/hummingbot/lib/python3.8/site-packages/aiohttp/client.py", line 520, in _request
    conn = await self._connector.connect(
  File "/opt/anaconda3/envs/hummingbot/lib/python3.8/site-packages/aiohttp/connector.py", line 535, in connect
    proto = await self._create_connection(req, traces, timeout)
  File "/opt/anaconda3/envs/hummingbot/lib/python3.8/site-packages/aiohttp/connector.py", line 892, in _create_connection
    _, proto = await self._create_direct_connection(req, traces, timeout)
  File "/opt/anaconda3/envs/hummingbot/lib/python3.8/site-packages/aiohttp/connector.py", line 1011, in _create_direct_connection
    raise ClientConnectorError(req.connection_key, exc) from exc
aiohttp.client_exceptions.ClientConnectorError: Cannot connect to host openapi.digifinex.com:443 ssl:default [nodename nor servname provided, or not known]
2022-09-14 08:49:24,761 - 95497 - hummingbot.connector.exchange.digifinex.time_patcher - WARNING - Could not refresh Digifinex server time. Check network connection.
2022-09-14 08:50:24,767 - 95497 - hummingbot.connector.exchange.digifinex.time_patcher - NETWORK - Error getting Digifinex server time.
Traceback (most recent call last):
  File "/opt/anaconda3/envs/hummingbot/lib/python3.8/site-packages/aiohttp/connector.py", line 999, in _create_direct_connection
    hosts = await asyncio.shield(host_resolved)
  File "/opt/anaconda3/envs/hummingbot/lib/python3.8/site-packages/aiohttp/connector.py", line 865, in _resolve_host
    addrs = await self._resolver.resolve(host, port, family=self._family)
  File "/opt/anaconda3/envs/hummingbot/lib/python3.8/site-packages/aiohttp/resolver.py", line 31, in resolve
    infos = await self._loop.getaddrinfo(
  File "/opt/anaconda3/envs/hummingbot/lib/python3.8/asyncio/base_events.py", line 825, in getaddrinfo
    return await self.run_in_executor(
  File "/opt/anaconda3/envs/hummingbot/lib/python3.8/concurrent/futures/thread.py", line 57, in run
    result = self.fn(*self.args, **self.kwargs)
  File "/opt/anaconda3/envs/hummingbot/lib/python3.8/socket.py", line 918, in getaddrinfo
    for res in _socket.getaddrinfo(host, port, family, type, proto, flags):
socket.gaierror: [Errno 8] nodename nor servname provided, or not known

The above exception was the direct cause of the following exception:

Traceback (most recent call last):
  File "/Users/clarasoutullo/projects/hummingbot/hummingbot/connector/exchange/digifinex/time_patcher.py", line 96, in update_server_time_offset
    server_time = await query_time_func()
  File "/Users/clarasoutullo/projects/hummingbot/hummingbot/connector/exchange/digifinex/digifinex_auth.py", line 40, in query_time_func
    async with session.get(Constants.REST_URL + '/time') as resp:
  File "/opt/anaconda3/envs/hummingbot/lib/python3.8/site-packages/aiohttp/client.py", line 1117, in __aenter__
    self._resp = await self._coro
  File "/opt/anaconda3/envs/hummingbot/lib/python3.8/site-packages/aiohttp/client.py", line 520, in _request
    conn = await self._connector.connect(
  File "/opt/anaconda3/envs/hummingbot/lib/python3.8/site-packages/aiohttp/connector.py", line 535, in connect
    proto = await self._create_connection(req, traces, timeout)
  File "/opt/anaconda3/envs/hummingbot/lib/python3.8/site-packages/aiohttp/connector.py", line 892, in _create_connection
    _, proto = await self._create_direct_connection(req, traces, timeout)
  File "/opt/anaconda3/envs/hummingbot/lib/python3.8/site-packages/aiohttp/connector.py", line 1011, in _create_direct_connection
    raise ClientConnectorError(req.connection_key, exc) from exc
aiohttp.client_exceptions.ClientConnectorError: Cannot connect to host openapi.digifinex.com:443 ssl:default [nodename nor servname provided, or not known]
2022-09-14 08:50:24,770 - 95497 - hummingbot.connector.exchange.digifinex.time_patcher - WARNING - Could not refresh Digifinex server time. Check network connection.
2022-09-14 11:07:10,427 - 95497 - hummingbot.connector.exchange.digifinex.time_patcher - NETWORK - Error getting Digifinex server time.
Traceback (most recent call last):
  File "/opt/anaconda3/envs/hummingbot/lib/python3.8/site-packages/aiohttp/connector.py", line 999, in _create_direct_connection
    hosts = await asyncio.shield(host_resolved)
  File "/opt/anaconda3/envs/hummingbot/lib/python3.8/site-packages/aiohttp/connector.py", line 865, in _resolve_host
    addrs = await self._resolver.resolve(host, port, family=self._family)
  File "/opt/anaconda3/envs/hummingbot/lib/python3.8/site-packages/aiohttp/resolver.py", line 31, in resolve
    infos = await self._loop.getaddrinfo(
  File "/opt/anaconda3/envs/hummingbot/lib/python3.8/asyncio/base_events.py", line 825, in getaddrinfo
    return await self.run_in_executor(
  File "/opt/anaconda3/envs/hummingbot/lib/python3.8/concurrent/futures/thread.py", line 57, in run
    result = self.fn(*self.args, **self.kwargs)
  File "/opt/anaconda3/envs/hummingbot/lib/python3.8/socket.py", line 918, in getaddrinfo
    for res in _socket.getaddrinfo(host, port, family, type, proto, flags):
socket.gaierror: [Errno 8] nodename nor servname provided, or not known

The above exception was the direct cause of the following exception:

Traceback (most recent call last):
  File "/Users/clarasoutullo/projects/hummingbot/hummingbot/connector/exchange/digifinex/time_patcher.py", line 96, in update_server_time_offset
    server_time = await query_time_func()
  File "/Users/clarasoutullo/projects/hummingbot/hummingbot/connector/exchange/digifinex/digifinex_auth.py", line 40, in query_time_func
    async with session.get(Constants.REST_URL + '/time') as resp:
  File "/opt/anaconda3/envs/hummingbot/lib/python3.8/site-packages/aiohttp/client.py", line 1117, in __aenter__
    self._resp = await self._coro
  File "/opt/anaconda3/envs/hummingbot/lib/python3.8/site-packages/aiohttp/client.py", line 520, in _request
    conn = await self._connector.connect(
  File "/opt/anaconda3/envs/hummingbot/lib/python3.8/site-packages/aiohttp/connector.py", line 535, in connect
    proto = await self._create_connection(req, traces, timeout)
  File "/opt/anaconda3/envs/hummingbot/lib/python3.8/site-packages/aiohttp/connector.py", line 892, in _create_connection
    _, proto = await self._create_direct_connection(req, traces, timeout)
  File "/opt/anaconda3/envs/hummingbot/lib/python3.8/site-packages/aiohttp/connector.py", line 1011, in _create_direct_connection
    raise ClientConnectorError(req.connection_key, exc) from exc
aiohttp.client_exceptions.ClientConnectorError: Cannot connect to host openapi.digifinex.com:443 ssl:default [nodename nor servname provided, or not known]
2022-09-14 11:07:10,448 - 95497 - hummingbot.connector.exchange.digifinex.time_patcher - WARNING - Could not refresh Digifinex server time. Check network connection.
2022-09-14 18:08:35,227 - 95497 - hummingbot.connector.exchange.digifinex.time_patcher - NETWORK - Error getting Digifinex server time.
Traceback (most recent call last):
  File "/opt/anaconda3/envs/hummingbot/lib/python3.8/site-packages/aiohttp/connector.py", line 999, in _create_direct_connection
    hosts = await asyncio.shield(host_resolved)
  File "/opt/anaconda3/envs/hummingbot/lib/python3.8/site-packages/aiohttp/connector.py", line 865, in _resolve_host
    addrs = await self._resolver.resolve(host, port, family=self._family)
  File "/opt/anaconda3/envs/hummingbot/lib/python3.8/site-packages/aiohttp/resolver.py", line 31, in resolve
    infos = await self._loop.getaddrinfo(
  File "/opt/anaconda3/envs/hummingbot/lib/python3.8/asyncio/base_events.py", line 825, in getaddrinfo
    return await self.run_in_executor(
  File "/opt/anaconda3/envs/hummingbot/lib/python3.8/concurrent/futures/thread.py", line 57, in run
    result = self.fn(*self.args, **self.kwargs)
  File "/opt/anaconda3/envs/hummingbot/lib/python3.8/socket.py", line 918, in getaddrinfo
    for res in _socket.getaddrinfo(host, port, family, type, proto, flags):
socket.gaierror: [Errno 8] nodename nor servname provided, or not known

The above exception was the direct cause of the following exception:

Traceback (most recent call last):
  File "/Users/clarasoutullo/projects/hummingbot/hummingbot/connector/exchange/digifinex/time_patcher.py", line 96, in update_server_time_offset
    server_time = await query_time_func()
  File "/Users/clarasoutullo/projects/hummingbot/hummingbot/connector/exchange/digifinex/digifinex_auth.py", line 40, in query_time_func
    async with session.get(Constants.REST_URL + '/time') as resp:
  File "/opt/anaconda3/envs/hummingbot/lib/python3.8/site-packages/aiohttp/client.py", line 1117, in __aenter__
    self._resp = await self._coro
  File "/opt/anaconda3/envs/hummingbot/lib/python3.8/site-packages/aiohttp/client.py", line 520, in _request
    conn = await self._connector.connect(
  File "/opt/anaconda3/envs/hummingbot/lib/python3.8/site-packages/aiohttp/connector.py", line 535, in connect
    proto = await self._create_connection(req, traces, timeout)
  File "/opt/anaconda3/envs/hummingbot/lib/python3.8/site-packages/aiohttp/connector.py", line 892, in _create_connection
    _, proto = await self._create_direct_connection(req, traces, timeout)
  File "/opt/anaconda3/envs/hummingbot/lib/python3.8/site-packages/aiohttp/connector.py", line 1011, in _create_direct_connection
    raise ClientConnectorError(req.connection_key, exc) from exc
aiohttp.client_exceptions.ClientConnectorError: Cannot connect to host openapi.digifinex.com:443 ssl:default [nodename nor servname provided, or not known]
2022-09-14 18:08:35,232 - 95497 - hummingbot.connector.exchange.digifinex.time_patcher - WARNING - Could not refresh Digifinex server time. Check network connection.
2022-09-14 18:40:32,881 - 95497 - hummingbot.connector.exchange.digifinex.time_patcher - NETWORK - Error getting Digifinex server time.
Traceback (most recent call last):
  File "/opt/anaconda3/envs/hummingbot/lib/python3.8/site-packages/aiohttp/connector.py", line 999, in _create_direct_connection
    hosts = await asyncio.shield(host_resolved)
  File "/opt/anaconda3/envs/hummingbot/lib/python3.8/site-packages/aiohttp/connector.py", line 865, in _resolve_host
    addrs = await self._resolver.resolve(host, port, family=self._family)
  File "/opt/anaconda3/envs/hummingbot/lib/python3.8/site-packages/aiohttp/resolver.py", line 31, in resolve
    infos = await self._loop.getaddrinfo(
  File "/opt/anaconda3/envs/hummingbot/lib/python3.8/asyncio/base_events.py", line 825, in getaddrinfo
    return await self.run_in_executor(
  File "/opt/anaconda3/envs/hummingbot/lib/python3.8/concurrent/futures/thread.py", line 57, in run
    result = self.fn(*self.args, **self.kwargs)
  File "/opt/anaconda3/envs/hummingbot/lib/python3.8/socket.py", line 918, in getaddrinfo
    for res in _socket.getaddrinfo(host, port, family, type, proto, flags):
socket.gaierror: [Errno 8] nodename nor servname provided, or not known

The above exception was the direct cause of the following exception:

Traceback (most recent call last):
  File "/Users/clarasoutullo/projects/hummingbot/hummingbot/connector/exchange/digifinex/time_patcher.py", line 96, in update_server_time_offset
    server_time = await query_time_func()
  File "/Users/clarasoutullo/projects/hummingbot/hummingbot/connector/exchange/digifinex/digifinex_auth.py", line 40, in query_time_func
    async with session.get(Constants.REST_URL + '/time') as resp:
  File "/opt/anaconda3/envs/hummingbot/lib/python3.8/site-packages/aiohttp/client.py", line 1117, in __aenter__
    self._resp = await self._coro
  File "/opt/anaconda3/envs/hummingbot/lib/python3.8/site-packages/aiohttp/client.py", line 520, in _request
    conn = await self._connector.connect(
  File "/opt/anaconda3/envs/hummingbot/lib/python3.8/site-packages/aiohttp/connector.py", line 535, in connect
    proto = await self._create_connection(req, traces, timeout)
  File "/opt/anaconda3/envs/hummingbot/lib/python3.8/site-packages/aiohttp/connector.py", line 892, in _create_connection
    _, proto = await self._create_direct_connection(req, traces, timeout)
  File "/opt/anaconda3/envs/hummingbot/lib/python3.8/site-packages/aiohttp/connector.py", line 1011, in _create_direct_connection
    raise ClientConnectorError(req.connection_key, exc) from exc
aiohttp.client_exceptions.ClientConnectorError: Cannot connect to host openapi.digifinex.com:443 ssl:default [nodename nor servname provided, or not known]
2022-09-14 18:40:32,883 - 95497 - hummingbot.connector.exchange.digifinex.time_patcher - WARNING - Could not refresh Digifinex server time. Check network connection.
2022-09-14 19:08:01,538 - 95497 - hummingbot.connector.exchange.digifinex.time_patcher - NETWORK - Error getting Digifinex server time.
Traceback (most recent call last):
  File "/opt/anaconda3/envs/hummingbot/lib/python3.8/site-packages/aiohttp/connector.py", line 999, in _create_direct_connection
    hosts = await asyncio.shield(host_resolved)
  File "/opt/anaconda3/envs/hummingbot/lib/python3.8/site-packages/aiohttp/connector.py", line 865, in _resolve_host
    addrs = await self._resolver.resolve(host, port, family=self._family)
  File "/opt/anaconda3/envs/hummingbot/lib/python3.8/site-packages/aiohttp/resolver.py", line 31, in resolve
    infos = await self._loop.getaddrinfo(
  File "/opt/anaconda3/envs/hummingbot/lib/python3.8/asyncio/base_events.py", line 825, in getaddrinfo
    return await self.run_in_executor(
  File "/opt/anaconda3/envs/hummingbot/lib/python3.8/concurrent/futures/thread.py", line 57, in run
    result = self.fn(*self.args, **self.kwargs)
  File "/opt/anaconda3/envs/hummingbot/lib/python3.8/socket.py", line 918, in getaddrinfo
    for res in _socket.getaddrinfo(host, port, family, type, proto, flags):
socket.gaierror: [Errno 8] nodename nor servname provided, or not known

The above exception was the direct cause of the following exception:

Traceback (most recent call last):
  File "/Users/clarasoutullo/projects/hummingbot/hummingbot/connector/exchange/digifinex/time_patcher.py", line 96, in update_server_time_offset
    server_time = await query_time_func()
  File "/Users/clarasoutullo/projects/hummingbot/hummingbot/connector/exchange/digifinex/digifinex_auth.py", line 40, in query_time_func
    async with session.get(Constants.REST_URL + '/time') as resp:
  File "/opt/anaconda3/envs/hummingbot/lib/python3.8/site-packages/aiohttp/client.py", line 1117, in __aenter__
    self._resp = await self._coro
  File "/opt/anaconda3/envs/hummingbot/lib/python3.8/site-packages/aiohttp/client.py", line 520, in _request
    conn = await self._connector.connect(
  File "/opt/anaconda3/envs/hummingbot/lib/python3.8/site-packages/aiohttp/connector.py", line 535, in connect
    proto = await self._create_connection(req, traces, timeout)
  File "/opt/anaconda3/envs/hummingbot/lib/python3.8/site-packages/aiohttp/connector.py", line 892, in _create_connection
    _, proto = await self._create_direct_connection(req, traces, timeout)
  File "/opt/anaconda3/envs/hummingbot/lib/python3.8/site-packages/aiohttp/connector.py", line 1011, in _create_direct_connection
    raise ClientConnectorError(req.connection_key, exc) from exc
aiohttp.client_exceptions.ClientConnectorError: Cannot connect to host openapi.digifinex.com:443 ssl:default [nodename nor servname provided, or not known]
2022-09-14 19:08:01,542 - 95497 - hummingbot.connector.exchange.digifinex.time_patcher - WARNING - Could not refresh Digifinex server time. Check network connection.
2022-09-14 19:09:06,353 - 95497 - hummingbot.connector.exchange.digifinex.time_patcher - NETWORK - Error getting Digifinex server time.
Traceback (most recent call last):
  File "/opt/anaconda3/envs/hummingbot/lib/python3.8/site-packages/aiohttp/connector.py", line 999, in _create_direct_connection
    hosts = await asyncio.shield(host_resolved)
  File "/opt/anaconda3/envs/hummingbot/lib/python3.8/site-packages/aiohttp/connector.py", line 865, in _resolve_host
    addrs = await self._resolver.resolve(host, port, family=self._family)
  File "/opt/anaconda3/envs/hummingbot/lib/python3.8/site-packages/aiohttp/resolver.py", line 31, in resolve
    infos = await self._loop.getaddrinfo(
  File "/opt/anaconda3/envs/hummingbot/lib/python3.8/asyncio/base_events.py", line 825, in getaddrinfo
    return await self.run_in_executor(
  File "/opt/anaconda3/envs/hummingbot/lib/python3.8/concurrent/futures/thread.py", line 57, in run
    result = self.fn(*self.args, **self.kwargs)
  File "/opt/anaconda3/envs/hummingbot/lib/python3.8/socket.py", line 918, in getaddrinfo
    for res in _socket.getaddrinfo(host, port, family, type, proto, flags):
socket.gaierror: [Errno 8] nodename nor servname provided, or not known

The above exception was the direct cause of the following exception:

Traceback (most recent call last):
  File "/Users/clarasoutullo/projects/hummingbot/hummingbot/connector/exchange/digifinex/time_patcher.py", line 96, in update_server_time_offset
    server_time = await query_time_func()
  File "/Users/clarasoutullo/projects/hummingbot/hummingbot/connector/exchange/digifinex/digifinex_auth.py", line 40, in query_time_func
    async with session.get(Constants.REST_URL + '/time') as resp:
  File "/opt/anaconda3/envs/hummingbot/lib/python3.8/site-packages/aiohttp/client.py", line 1117, in __aenter__
    self._resp = await self._coro
  File "/opt/anaconda3/envs/hummingbot/lib/python3.8/site-packages/aiohttp/client.py", line 520, in _request
    conn = await self._connector.connect(
  File "/opt/anaconda3/envs/hummingbot/lib/python3.8/site-packages/aiohttp/connector.py", line 535, in connect
    proto = await self._create_connection(req, traces, timeout)
  File "/opt/anaconda3/envs/hummingbot/lib/python3.8/site-packages/aiohttp/connector.py", line 892, in _create_connection
    _, proto = await self._create_direct_connection(req, traces, timeout)
  File "/opt/anaconda3/envs/hummingbot/lib/python3.8/site-packages/aiohttp/connector.py", line 1011, in _create_direct_connection
    raise ClientConnectorError(req.connection_key, exc) from exc
aiohttp.client_exceptions.ClientConnectorError: Cannot connect to host openapi.digifinex.com:443 ssl:default [nodename nor servname provided, or not known]
2022-09-14 19:09:06,356 - 95497 - hummingbot.connector.exchange.digifinex.time_patcher - WARNING - Could not refresh Digifinex server time. Check network connection.
2022-09-15 01:36:45,856 - 95497 - hummingbot.connector.exchange.digifinex.time_patcher - NETWORK - Error getting Digifinex server time.
Traceback (most recent call last):
  File "/Users/clarasoutullo/projects/hummingbot/hummingbot/connector/exchange/digifinex/time_patcher.py", line 96, in update_server_time_offset
    server_time = await query_time_func()
  File "/Users/clarasoutullo/projects/hummingbot/hummingbot/connector/exchange/digifinex/digifinex_auth.py", line 40, in query_time_func
    async with session.get(Constants.REST_URL + '/time') as resp:
  File "/opt/anaconda3/envs/hummingbot/lib/python3.8/site-packages/aiohttp/client.py", line 1117, in __aenter__
    self._resp = await self._coro
  File "/opt/anaconda3/envs/hummingbot/lib/python3.8/site-packages/aiohttp/client.py", line 544, in _request
    await resp.start(conn)
  File "/opt/anaconda3/envs/hummingbot/lib/python3.8/site-packages/aiohttp/client_reqrep.py", line 890, in start
    message, payload = await self._protocol.read()  # type: ignore
  File "/opt/anaconda3/envs/hummingbot/lib/python3.8/site-packages/aiohttp/streams.py", line 604, in read
    await self._waiter
aiohttp.client_exceptions.ClientOSError: [Errno 54] Connection reset by peer
2022-09-15 01:36:45,862 - 95497 - hummingbot.connector.exchange.digifinex.time_patcher - WARNING - Could not refresh Digifinex server time. Check network connection.
2022-09-15 02:21:01,734 - 95497 - hummingbot.connector.exchange.digifinex.time_patcher - NETWORK - Error getting Digifinex server time.
Traceback (most recent call last):
  File "/opt/anaconda3/envs/hummingbot/lib/python3.8/site-packages/aiohttp/connector.py", line 999, in _create_direct_connection
    hosts = await asyncio.shield(host_resolved)
  File "/opt/anaconda3/envs/hummingbot/lib/python3.8/site-packages/aiohttp/connector.py", line 865, in _resolve_host
    addrs = await self._resolver.resolve(host, port, family=self._family)
  File "/opt/anaconda3/envs/hummingbot/lib/python3.8/site-packages/aiohttp/resolver.py", line 31, in resolve
    infos = await self._loop.getaddrinfo(
  File "/opt/anaconda3/envs/hummingbot/lib/python3.8/asyncio/base_events.py", line 825, in getaddrinfo
    return await self.run_in_executor(
  File "/opt/anaconda3/envs/hummingbot/lib/python3.8/concurrent/futures/thread.py", line 57, in run
    result = self.fn(*self.args, **self.kwargs)
  File "/opt/anaconda3/envs/hummingbot/lib/python3.8/socket.py", line 918, in getaddrinfo
    for res in _socket.getaddrinfo(host, port, family, type, proto, flags):
socket.gaierror: [Errno 8] nodename nor servname provided, or not known

The above exception was the direct cause of the following exception:

Traceback (most recent call last):
  File "/Users/clarasoutullo/projects/hummingbot/hummingbot/connector/exchange/digifinex/time_patcher.py", line 96, in update_server_time_offset
    server_time = await query_time_func()
  File "/Users/clarasoutullo/projects/hummingbot/hummingbot/connector/exchange/digifinex/digifinex_auth.py", line 40, in query_time_func
    async with session.get(Constants.REST_URL + '/time') as resp:
  File "/opt/anaconda3/envs/hummingbot/lib/python3.8/site-packages/aiohttp/client.py", line 1117, in __aenter__
    self._resp = await self._coro
  File "/opt/anaconda3/envs/hummingbot/lib/python3.8/site-packages/aiohttp/client.py", line 520, in _request
    conn = await self._connector.connect(
  File "/opt/anaconda3/envs/hummingbot/lib/python3.8/site-packages/aiohttp/connector.py", line 535, in connect
    proto = await self._create_connection(req, traces, timeout)
  File "/opt/anaconda3/envs/hummingbot/lib/python3.8/site-packages/aiohttp/connector.py", line 892, in _create_connection
    _, proto = await self._create_direct_connection(req, traces, timeout)
  File "/opt/anaconda3/envs/hummingbot/lib/python3.8/site-packages/aiohttp/connector.py", line 1011, in _create_direct_connection
    raise ClientConnectorError(req.connection_key, exc) from exc
aiohttp.client_exceptions.ClientConnectorError: Cannot connect to host openapi.digifinex.com:443 ssl:default [nodename nor servname provided, or not known]
2022-09-15 02:21:01,744 - 95497 - hummingbot.connector.exchange.digifinex.time_patcher - WARNING - Could not refresh Digifinex server time. Check network connection.
2022-09-15 02:50:13,445 - 95497 - hummingbot.connector.exchange.digifinex.time_patcher - NETWORK - Error getting Digifinex server time.
Traceback (most recent call last):
  File "/Users/clarasoutullo/projects/hummingbot/hummingbot/connector/exchange/digifinex/time_patcher.py", line 96, in update_server_time_offset
    server_time = await query_time_func()
  File "/Users/clarasoutullo/projects/hummingbot/hummingbot/connector/exchange/digifinex/digifinex_auth.py", line 40, in query_time_func
    async with session.get(Constants.REST_URL + '/time') as resp:
  File "/opt/anaconda3/envs/hummingbot/lib/python3.8/site-packages/aiohttp/client.py", line 1117, in __aenter__
    self._resp = await self._coro
  File "/opt/anaconda3/envs/hummingbot/lib/python3.8/site-packages/aiohttp/client.py", line 544, in _request
    await resp.start(conn)
  File "/opt/anaconda3/envs/hummingbot/lib/python3.8/site-packages/aiohttp/client_reqrep.py", line 890, in start
    message, payload = await self._protocol.read()  # type: ignore
  File "/opt/anaconda3/envs/hummingbot/lib/python3.8/site-packages/aiohttp/streams.py", line 604, in read
    await self._waiter
aiohttp.client_exceptions.ClientOSError: [Errno 54] Connection reset by peer
2022-09-15 02:50:13,447 - 95497 - hummingbot.connector.exchange.digifinex.time_patcher - WARNING - Could not refresh Digifinex server time. Check network connection.
